Workbook

Sheet Sal-div
D2: A | E2: B | G2: Inkomstenbelasting 2025 | K2: A | M2: Inkomstenbelasting 2025 | Q2: B
B3: vul in | C3: Brutoloon | D3: =T9 -> 72636.24 | E3: =T14 -> 77479.773 | G3: Van | H3: Tot en met | M3: Van | N3: Tot en met | S3: A | T3: =5614.64*12*1.08+(12*53.23)+1000 -> 74404.494
B4: vul in | C4: Bijtelling auto | D4: =605.07*12 -> 7260.84 | E4: =D4 -> 7260.84 | G4: 0 | H4: 38440 | I4: =IF(J5=TRUE,H4,IF(J6=TRUE,H4,$D$8)) -> 38440 | J4: =AND($D$8<=H4) -> FALSE | K4: 0.3697 | M4: 0 | N4: 38440 | O4: =IF(P5=TRUE,N4,IF(P6=TRUE,N4,$E$8)) -> 38440 | P4: =AND($E$8<=N4) -> FALSE | Q4: 0.3697 | S4: bruto Subtotaal | T4: 77550
B5: vul in | C5: Hypotheekrenteaftrek | D5: 0 | E5: 0 | G5: =H4+1 -> 38441 | H5: 76816 | I5: =IF(J5=TRUE,$D$8-I4,IF(J6=TRUE,H5-H4,0)) -> 38376 | J5: =AND($D$8>=G5,$D$8<=H5) -> FALSE | K5: 0.3748 | M5: =N4+1 -> 38441 | N5: 76816 | O5: =IF(P5=TRUE,$E$8-O4,IF(P6=TRUE,N5-N4,0)) -> 38376 | P5: =AND($E$8>=M5,$E$8<=N5) -> FALSE | Q5: 0.3748 | S5: pensioen | T5: =12*180.97 -> 2171.64
B6: vul in | C6: Premie AOV | D6: 0 | E6: 0 | G6: =H5+1 -> 76817 | H6: 0 | I6: =IF(J6=TRUE,$D$8-H5,IF(J6=FALSE,0,$D$8*K6)) -> 921.08 | J6: =AND($D$8>=G6) -> TRUE | K6: 0.495 | M6: =N5+1 -> 76817 | N6: 0 | O6: =IF(P6=TRUE,$E$8-N5,IF(P6=FALSE,0,$E$8*Q6)) -> 5764.6128 | P6: =AND($E$8>=M6) -> TRUE | Q6: 0.495 | S6: whk | T6: =6.01*12 -> 72.12
B7: vul in | C7: Pensioenpremie | D7: =180*12 -> 2160 | E7: =D7 -> 2160 | I7: =SUM(I4:I6) -> 77737.08 | K7: =(K4*I4)+(I5*K5)+(I6*K6) -> 29050.527 | O7: =SUM(O4:O6) -> 82580.613 | Q7: =(Q4*O4)+(O5*Q5)+(O6*Q6) -> 31448.076 | S7: 1 malige loonheffing | T7: =560+2110 -> 2670
C8: Belastbaar inkomen box 1 | D8: =D3+D4-D5-D6-D7 -> 77737.08 | E8: =E3+E4-E5-E6-E7 -> 82580.613
C9: Inkomstenbelasting | D9: =ROUNDDOWN(K7+I13-I22-I29,0) -> 29698 | E9: =ROUNDDOWN(Q7+O13-O22-O29,0) -> 32411 | G9: Bijdrage ZVW 2025 | K9: A | M9: Bijdrage ZVW 2025 | Q9: B | S9: brutoloon totaal | T9: =T4-T5-T6-T7-T8 -> 72636.24
G10: Van | H10: Tot en met | M10: Van | N10: Tot en met | S10: belasting | T10: =K7-I22 -> 25708.289
B11: vul in | C11: Bruto dividend | D11: 0 | E11: 0 | G11: 0 | H11: 75864 | I11: =IF(J11=TRUE,D8*K11,0) -> 0 | J11: =AND($D$8<=H11) -> FALSE | K11: 0.0526 | M11: 0 | N11: 75864 | O11: =IF(P11=TRUE,E8*Q11,0) -> 0 | P11: =AND($E$8<=N11) -> FALSE | Q11: 0.0526 | S11: netto | T11: =T9-T10 -> 46927.951
B12: vul in | C12: Fiscale partner? ja/nee | D12: nee | E12: nee | G12: =H11+1 -> 75865 | H12: 0 | I12: =IF(J12=TRUE,3990,0) -> 3990 | J12: =AND($D$8>H11) -> TRUE | K12: 0 | M12: =N11+1 -> 75865 | N12: 0 | O12: =IF(P12=TRUE,3990,0) -> 3990 | P12: =AND($E$8>N11) -> TRUE | Q12: 0
C13: Hoogste percentage DIB | D13: =IF(AND(D11>67804,D12="nee"),31%,IF(AND(D11>135608,D12="ja"),31%,24.5%)) -> 0.245 | E13: =IF(AND(E11>67804,E12="nee"),31%,IF(AND(E11>135608,E12="ja"),31%,24.5%)) -> 0.245 | I13: =ROUNDDOWN(SUM(I11:I12),0) -> 3990 | O13: =ROUNDDOWN(SUM(O11:O12),0) -> 3990
C14: Dividendbelasting | D14: =IF(D12="ja",I41,I35) -> 0 | E14: =IF(E12="ja",O41,O35) -> 0 | S14: B | T14: =5851.93*12*1.08+(12*53.23)+1000 -> 77479.773
G15: Arbeidskorting 2025 | K15: A | M15: Arbeidskorting 2025 | Q15: B | S15: brutoloon totaal | T15: =E3 -> 77479.773
G16: Van | H16: Tot en met | M16: Van | N16: Tot en met | S16: belasting | T16: =Q7-O22 -> 28421.152
C17: Netto salaris | D17: =D3-D9 -> 42938.24 | E17: =E3-E9 -> 45068.773 | G17: 0 | H17: 12168 | I17: =IF(J17=TRUE,$D$8*K17,0) -> 0 | J17: =AND($D$8<=H17) -> FALSE | K17: 0.08053 | M17: 0 | N17: 12168 | O17: =IF(P17=TRUE,$E$8*Q17,0) -> 0 | P17: =AND($E$8<=N17) -> FALSE | Q17: 0.08053 | S17: netto | T17: =T15-T16 -> 49058.621
C18: Netto dividend | D18: =D11-D14 -> 0 | E18: =E11-E14 -> 0 | G18: =H17+1 -> 12169 | H18: 26287 | I18: =IF(J18=TRUE,980+($D$8-G18)*K18,0) -> 0 | J18: =AND($D$8>=G18,$D$8<=H18) -> FALSE | K18: 0.3003 | M18: =N17+1 -> 12169 | N18: 26287 | O18: =IF(P18=TRUE,980+($E$8-M18)*Q18,0) -> 0 | P18: =AND($E$8>=M18,$E$8<=N18) -> FALSE | Q18: 0.3003
C19: Netto totaal in privé | D19: =SUM(D17:D18) -> 42938.24 | E19: =SUM(E17:E18) -> 45068.773 | G19: =H18+1 -> 26288 | H19: 43070 | I19: =IF(J19=TRUE,5220+($D$8-G19)*K19,0) -> 0 | J19: =AND($D$8>=G19,$D$8<=H19) -> FALSE | K19: 0.02258 | M19: =N18+1 -> 26288 | N19: 43070 | O19: =IF(P19=TRUE,5220+($E$8-M19)*Q19,0) -> 0 | P19: =AND($E$8>=M19,$E$8<=N19) -> FALSE | Q19: 0.02258
G20: =H19+1 -> 43071 | H20: 129077 | I20: =IF(J20=TRUE,5599-($D$8-G20)*K20,0) -> 3342.2382 | J20: =AND($D$8>=G20,$D$8<=H20) -> TRUE | K20: 0.0651 | M20: =N19+1 -> 43071 | N20: 129077 | O20: =IF(P20=TRUE,5599-($E$8-M20)*Q20,0) -> 3026.9242 | P20: =AND($E$8>=M20,$E$8<=N20) -> TRUE | Q20: 0.0651
C21: Inkomstenbelasting | D21: =D9 -> 29698 | E21: =E9 -> 32411 | G21: =H20+1 -> 129078 | H21: 0 | I21: =IF(J21=TRUE,K21,0) -> 0 | J21: =AND($D$8>=G21) -> FALSE | K21: 0 | M21: =N20+1 -> 129078 | N21: 0 | O21: =IF(P21=TRUE,Q21,0) -> 0 | P21: =AND($E$8>=M21) -> FALSE | Q21: 0
C22: Dividendbelasting | D22: =D14 -> 0 | E22: =E14 -> 0 | I22: =SUM(I17:I21) -> 3342.2382 | O22: =SUM(O17:O21) -> 3026.9242
C23: Besparing VPB | D23: =IF($D$3<$E$3,0,$E$3-$D$3)*D33 -> 0 | E23: =IF($D$3>$E$3,0,$D$3-$E$3)*E33 -> -920.27123
C24: Totale belasting | D24: =SUM(D21:D23) -> 29698 | E24: =SUM(E21:E23) -> 31490.729 | F24: =E24-D24 -> 1792.7288 | G24: Algemene heffingskorting 2025 | K24: A | M24: Algemene heffingskorting 2025 | Q24: B
G25: Van | H25: Tot en met | M25: Van | N25: Tot en met
G26: 0 | H26: 28405 | I26: =IF(J26=TRUE,K26,0) -> 0 | J26: =AND($D$27<=H26) -> FALSE | K26: 3068 | M26: 0 | N26: 28405 | O26: =IF(P26=TRUE,Q26,0) -> 0 | P26: =AND($E$27<=N26) -> FALSE | Q26: 3068
C27: Verzamelinkomen box 1 + 2 | D27: =IF(D12="ja",D8+(D11/2),D8+D11) -> 77737.08 | E27: =IF(E12="ja",E8+(E11/2),E8+E11) -> 82580.613 | G27: =H26+1 -> 28406 | H27: 76816 | I27: =IF(J27=TRUE,K26-(K27*($D$8-G27)),0) -> 0 | J27: =AND($D$27>=G27,$D$27<=H27) -> FALSE | K27: 0.06337 | M27: =N26+1 -> 28406 | N27: 76816 | O27: =IF(P27=TRUE,Q26-(Q27*($E$8-M27)),0) -> 0 | P27: =AND($E$27>=M27,$E$27<=N27) -> FALSE | Q27: 0.06337
G28: =H27+1 -> 76817 | H28: 0 | I28: =IF(J28=TRUE,K28,0) -> 0 | J28: =AND($D$27>=G28) -> TRUE | K28: 0 | M28: =N27+1 -> 76817 | N28: 0 | O28: =IF(P28=TRUE,Q28,0) -> 0 | P28: =AND($E$27>=M28) -> TRUE | Q28: 0
I29: =SUM(I26:I28) -> 0 | O29: =SUM(O26:O28) -> 0
B30: vul in | C30: Winst moeder voor salaris | D30: 0 | E30: 0
C31: Salaris DGA | D31: 0 | E31: 0 | G31: Dividendbelasting 2025 1 persoon | K31: A | M31: Dividendbelasting 2025 1 persoon | Q31: B
C32: Winst moeder na salaris | D32: =D30-D31 -> 0 | E32: =E30-E31 -> 0 | G32: Van | H32: Tot en met | M32: Van | N32: Tot en met
C33: Hoogste percentage VPB | D33: =IF(D32>200000,25.8%,19%) -> 0.19 | E33: =IF(E32>200000,25.8%,19%) -> 0.19 | G33: 0 | H33: 67804 | I33: =IF(J33=FALSE,H33*K33,K33*$D$11) -> 0 | J33: =AND($D$11<=H33) -> TRUE | K33: 0.245 | M33: 0 | N33: 67804 | O33: =IF(P33=FALSE,N33*Q33,Q33*$E$11) -> 0 | P33: =AND($E$11<=N33) -> TRUE | Q33: 0.245
G34: =H33+1 -> 67805 | H34: 0 | I34: =IF(J34=TRUE,($D$11-H33)*K34,0) -> 0 | J34: =AND($D$11>=G34) -> FALSE | K34: 0.31 | M34: =N33+1 -> 67805 | N34: 0 | O34: =IF(P34=TRUE,($E$11-N33)*Q34,0) -> 0 | P34: =AND($E$11>=M34) -> FALSE | Q34: 0.31
I35: =ROUNDDOWN(SUM(I33:I34),0) -> 0 | O35: =ROUNDDOWN(SUM(O33:O34),0) -> 0
G37: Dividendbelasting 2025 2 personen | K37: A | M37: Dividendbelasting 2025 2 personen | Q37: B
G38: Van | H38: Tot en met | M38: Van | N38: Tot en met
G39: 0 | H39: 135608 | I39: =IF(J39=FALSE,H39*K39,K39*$D$11) -> 0 | J39: =AND($D$11<=H39) -> TRUE | K39: 0.245 | M39: 0 | N39: 135608 | O39: =IF(P39=FALSE,N39*Q39,Q39*$E$11) -> 0 | P39: =AND($E$11<=N39) -> TRUE | Q39: 0.245
G40: =H39+1 -> 135609 | H40: 0 | I40: =IF(J40=TRUE,($D$11-H39)*K40,0) -> 0 | J40: =AND($D$11>=G40) -> FALSE | K40: 0.31 | M40: =N39+1 -> 135609 | N40: 0 | O40: =IF(P40=TRUE,($E$11-N39)*Q40,0) -> 0 | P40: =AND($E$11>=M40) -> FALSE | Q40: 0.31
I41: =ROUNDDOWN(SUM(I39:I40),0) -> 0 | O41: =ROUNDDOWN(SUM(O39:O40),0) -> 0

Sheet Rente tabel hypotheek
A1: website | B1: https://www.belastingdienst.nl/wps/wcm/connect/nl/koopwoning/content/hulpmiddel-aflossingsverplichting-annuiteitenlening-berekenen
A3: 2025
A4: Maand | B4: Betaling | C4: Betaalde rente | D4: Aflossing | E4: Resterende bedrag
A5: januari | B5: € 0 | C5: € 0 | D5: € 0 | E5: € 0
A6: februari | B6: € 0 | C6: € 0 | D6: € 0 | E6: € 0
A7: maart | B7: € 0 | C7: € 0 | D7: € 0 | E7: € 0
A8: april | B8: € 1258.01 | C8: € 836.46 | D8: € 421.56 | E8: € 274578.44
A9: mei | B9: € 1258.01 | C9: € 835.18 | D9: € 422.84 | E9: € 274155.61
A10: juni | B10: € 1258.01 | C10: € 833.89 | D10: € 424.12 | E10: € 273731.48
A11: juli | B11: € 1258.01 | C11: € 832.60 | D11: € 425.41 | E11: € 273306.07
A12: augustus | B12: € 1258.01 | C12: € 831.31 | D12: € 426.71 | E12: € 272879.36
A13: september | B13: € 1258.01 | C13: € 830.01 | D13: € 428.01 | E13: € 272451.36
A14: oktober | B14: € 1258.01 | C14: € 828.71 | D14: € 429.31 | E14: € 272022.05
A15: november | B15: € 1258.01 | C15: € 827.40 | D15: € 430.61 | E15: € 271591.43
A16: december | B16: € 1258.01 | C16: € 826.09 | D16: € 431.92 | E16: € 271159.51
A17: 2026
A18: januari | B18: € 1258.01 | C18: 824.78 | D18: 433.24 | E18: € 270726.27 | H18: =SUM(D18:D29) -> 5286.7 | J18: =271591-H18 -> 266304.3
A19: februari | B19: € 1258.01 | C19: 823.46 | D19: 434.55 | E19: € 270291.72 | H19: =SUM(C18:C29) -> 9809.47
A20: maart | B20: € 1258.01 | C20: 822.14 | D20: 435.88 | E20: € 269855.84
A21: april | B21: € 1258.01 | C21: 820.81 | D21: 437.2 | E21: € 269418.64
A22: mei | B22: € 1258.01 | C22: 819.48 | D22: 438.53 | E22: € 268980.11
A23: juni | B23: € 1258.01 | C23: 818.15 | D23: 439.87 | E23: € 268540.24
A24: juli | B24: € 1258.01 | C24: 816.81 | D24: 441.2 | E24: € 268099.04
A25: augustus | B25: € 1258.01 | C25: 815.47 | D25: 442.55 | E25: € 267656.49
A26: september | B26: € 1258.01 | C26: 814.12 | D26: 443.89 | E26: € 267212.60
A27: oktober | B27: € 1258.01 | C27: 812.77 | D27: 445.24 | E27: € 266767.36
A28: november | B28: € 1258.01 | C28: 811.42 | D28: 446.6 | E28: € 266320.76
A29: december | B29: € 1258.01 | C29: 810.06 | D29: 447.95 | E29: € 265872.81
A30: 2027
A31: januari | B31: € 1258.01 | C31: € 808.70 | D31: € 449.32 | E31: € 265423.49
A32: februari | B32: € 1258.01 | C32: € 807.33 | D32: € 450.68 | E32: € 264972.81
A33: maart | B33: € 1258.01 | C33: € 805.96 | D33: € 452.05 | E33: € 264520.75
A34: april | B34: € 1258.01 | C34: € 804.58 | D34: € 453.43 | E34: € 264067.32
A35: mei | B35: € 1258.01 | C35: € 803.20 | D35: € 454.81 | E35: € 263612.51
A36: juni | B36: € 1258.01 | C36: € 801.82 | D36: € 456.19 | E36: € 263156.32
A37: juli | B37: € 1258.01 | C37: € 800.43 | D37: € 457.58 | E37: € 262698.74
A38: augustus | B38: € 1258.01 | C38: € 799.04 | D38: € 458.97 | E38: € 262239.77
A39: september | B39: € 1258.01 | C39: € 797.65 | D39: € 460.37 | E39: € 261779.40
A40: oktober | B40: € 1258.01 | C40: € 796.25 | D40: € 461.77 | E40: € 261317.63
A41: november | B41: € 1258.01 | C41: € 794.84 | D41: € 463.17 | E41: € 260854.46
...

Sheet Stroom en Gas
A1: Naam | B1: Berekening | C1: Totalen | D1: Mei | E1: Juni | F1: Juli | G1: Augustus | H1: September | I1: Oktober | J1: November | K1: December | M1: Totaal per maand
A2: Normaaltarief (per kWh) | C2: 0.28522 | D2: =$C2*F40 -> 42.783 | E2: =$C2*G40 -> 27.95156 | F2: =$C2*H40 -> 33.37074 | G2: =$C2*I40 -> 25.95502 | H2: 0 | I2: 0 | J2: 0 | K2: 0 | M2: Mei | N2: Juni | O2: Juli | P2: Augustus | Q2: September | R2: Oktober | S2: November | T2: December | U2: Gemiddled
L3: stroom | M3: =(D2+D8+$D20+$D22)-$D24/12 -> 91.3478 | N3: =(E2+E8+$D20+$D22)-$D24/12 -> 83.08087 | O3: =(F2+F8+$D20+$D22)-$D24/12 -> 79.01798 | P3: =(G2+G8+$D20+$D22)-$D24/12 -> 69.65722 | Q3: =(H2+H8+$D20+$D22)-$D24/12 -> -2.4925 | R3: =(I2+I8+$D20+$D22)-$D24/12 -> -2.4925 | S3: =(J2+J8+$D20+$D22)-$D24/12 -> -2.4925 | T3: =(K2+K8+$D20+$D22)-$D24/12 -> -2.4925 | U3: =SUM(M3:P3)/4 -> 80.775968
A4: Elektriciteit | B4: 0.13418 | L4: gas | M4: =D28+$C34+$C36 -> 60.80691 | N4: =E28+$C34+$C36 -> 58.24457 | O4: =F28+$C34+$C36 -> 56.9634 | P4: =G28+$C34+$C36 -> 69.7751 | Q4: =H28+$C34+$C36 -> 82.5868 | R4: =I28+$C34+$C36 -> 95.3985 | S4: =J28+$C34+$C36 -> 95.3985 | T4: =K28+$C34+$C36 -> 95.3985 | U4: =SUM(M4:O4)/3 -> 58.671627
A5: Energiebelasting | B5: 0.10154 | L5: Totaal | M5: =M3+M4 -> 152.15471 | N5: =N3+N4 -> 141.32544 | O5: =O3+O4 -> 135.98138 | P5: =P3+P4 -> 139.43232 | Q5: =Q3+Q4 -> 80.0943 | R5: =R3+R4 -> 92.906 | S5: =S3+S4 -> 92.906 | T5: =T3+T4 -> 92.906 | U5: =SUM(M5:O5)/3 -> 143.15384
A6: Btw | B6: 0.0495
A7: Totaal | B7: 0.28522 | L7: Termijn stroom | M7: 23
A8: Daltarief (per kWh) | C8: 0.24313 | D8: =$C8*F39 -> 51.0573 | E8: =$C8*G39 -> 57.62181 | F8: =$C8*H39 -> 48.13974 | G8: =$C8*I39 -> 46.1947 | L8: termijn bedrag gas | M8: 117
A10: Electriciteit | B10: 0.09939
A11: Energiebelasting | B11: 0.10154
A12: Btw. | B12: 0.0422
A13: Totaal | B13: =SUM(B10:B12) -> 0.24313
A14: Terugleververgoeding normaal (per kWh) | M14: 8 Zonnepanelen
A15: € 0,10000 | N15: gebruik | O15: percentage van totaal | P15: opwek | Q15: stroom inkoop | R15: kosten inkoop totaal | S15: kosten per maand inkoop met panelen | T15: kosten per maand zonder panelen | U15: Per jaar
A16: Terugleververgoeding dal (per kWh) | M16: dal | N16: =$R39*12 -> 2797 | O16: =N16/N18*100 -> 60.423418 | P16: =O16/100*3500 -> 2114.8196 | Q16: =N16-P16 -> 682.18038 | R16: =Q16*C8 -> 165.85852 | S16: =R16/12 -> 13.821543 | T16: =N28*C8/12 -> 56.669551 | U16: =T16*12 -> 680.03461
A17: € 0,10000 | M17: normaal | N17: =$R40*12 -> 1832 | O17: =N17/N18*100 -> 39.576582 | P17: =O17/100*3500 -> 1385.1804 | Q17: =N17-P17 -> 446.81962 | R17: =Q17*C2 -> 127.44189 | S17: =R17/12 -> 10.620158 | T17: =N29*C2/12 -> 43.543587 | U17: =T17*12 -> 522.52304
A18: Vaste terugleveringskosten (per dag) | M18: totaal | N18: =SUM(N16:N17) -> 4629 | O18: =SUM(O16:O17) -> 100 | P18: =SUM(P16:P17) -> 3500 | Q18: =SUM(Q16:Q17) -> 1129 | R18: =SUM(R16:R17) -> 293.30041 | S18: =R18/12 -> 24.441701 | T18: =SUM(T16:T17) -> 100.21314 | U18: =T18*12 -> 1202.5576
A19: € 0,00000 | S19: Verschil | T19: =T18-S18 -> 75.771437 | U19: =T19*12 -> 909.25724
A20: Vaste leveringskosten (per maand) | C20: 10.78 | D20: 10.78 | S20: Kosten investering | T20: 49 | U20: =T20*12 -> 588
S21: winst per maand met investering | T21: =T19-T20 -> 26.771437 | U21: =T21*12 -> 321.25724
A22: Netbeheerkosten Enexis (per maand) | C22: 39.66 | D22: 39.66 | S22: uitgave per maand met zonnepanelen | T22: =S18+T20 -> 73.441701 | U22: =T22*12 -> 881.30041
S23: uitgave per maand zonder panelen | T23: =T18 -> 100.21314 | U23: =T23*12 -> 1202.5576
A24: Vermindering energiebelasting (per jaar) | C24: 635.19 | D24: 635.19 | S24: winst per maand met panelen | T24: =T23-T22 -> 26.771437 | U24: =T24*12 -> 321.25724
C25: =C24/12 -> 52.9325
A26: Gas tarieven | M26: 7 Zonnepanelen
A27: Tarief | N27: gebruik | O27: percentage van totaal | P27: opwek | Q27: stroom inkoop | R27: kosten inkoop totaal | S27: kosten per maand inkoop met panelen | T27: kosten per maand zonder panelen | U27: Per jaar
A28: Gastarief (per m³) | C28: 1.28117 | D28: =$C28*F42 -> 29.46691 | E28: =$C28*G42 -> 26.90457 | F28: =$C28*H42 -> 25.6234 | G28: =$C28*I42 -> 38.4351 | H28: =$C28*J42 -> 51.2468 | I28: =$C28*K42 -> 64.0585 | J28: =$C28*L42 -> 64.0585 | K28: =$C28*M42 -> 64.0585 | M28: dal | N28: =$R39*12 -> 2797 | O28: =N28/N30*100 -> 60.423418 | P28: =O28/100*3000 -> 1812.7025 | Q28: =N28-P28 -> 984.29747 | R28: =Q28*C8 -> 239.31224 | S28: =R28/12 -> 19.942687 | T28: =N28*C8/12 -> 56.669551 | U28: =T28*12 -> 680.03461
M29: normaal | N29: =$R40*12 -> 1832 | O29: =N29/N30*100 -> 39.576582 | P29: =O29/100*3000 -> 1187.2975 | Q29: =N29-P29 -> 644.70253 | R29: =Q29*C2 -> 183.88205 | S29: =R29/12 -> 15.323505 | T29: =N29*C2/12 -> 43.543587 | U29: =T29*12 -> 522.52304
A30: Gas | B30: 0.48066 | M30: totaal | N30: =SUM(N28:N29) -> 4629 | O30: =SUM(O28:O29) -> 100 | P30: =SUM(P28:P29) -> 3000 | Q30: =SUM(Q28:Q29) -> 1629 | R30: =SUM(R28:R29) -> 423.1943 | S30: =R30/12 -> 35.266192 | T30: =SUM(T28:T29) -> 100.21314 | U30: =T30*12 -> 1202.5576
A31: Energiebelasting | B31: 0.57816 | S31: Verschil | T31: =T30-S30 -> 64.946946 | U31: =T31*12 -> 779.36335
A32: Btw | B32: 0.22235 | S32: Kosten investering | T32: 49 | U32: =T32*12 -> 588
A33: Totaal | B33: 1.28117 | S33: winst per maand met investering | T33: =T31-T32 -> 15.946946 | U33: =T33*12 -> 191.36335
A34: Vaste leveringskosten (per maand) | C34: 10.83 | S34: uitgave per maand met zonnepanelen inclusief leveringskosten | T34: =S30+T32 -> 84.266192 | U34: =T34*12 -> 1011.1943
M35: Vaste kosten stroom en gas | S35: uitgave per maand zonder panelen | T35: =T30 -> 100.21314 | U35: =T35*12 -> 1202.5576
A36: Netbeheerkosten Enexis (per maand) | C36: 20.51 | M36: =C20+C22 -> 50.44 | S36: winst per maand met panelen | T36: =T35-T34 -> 15.946946 | U36: =T36*12 -> 191.36335
B38: Januari | C38: Februaru | D38: Maart | E38: April | F38: Mei | G38: juni | H38: juli | I38: augustus | J38: september | K38: oktober | L38: november | M38: december | O38: totaal | P38: gemiddelde | Q38: Per maand | S38: euro per maand
A39: Dal Kwh | B39: 307 | C39: 270 | D39: 275 | E39: 250 | F39: 210 | G39: 237 | H39: 198 | I39: 190 | J39: 200 | K39: 210 | L39: 220 | M39: 230 | O39: =SUM(B39:M39) -> 2797 | P39: =O39/12 -> 233.08333 | Q39: Dal gemiddelde | R39: =P39 -> 233.08333 | S39: =R39*C8 -> 56.669551
A40: normaal Kwh | B40: 144 | C40: 114 | D40: 122 | E40: 96 | F40: 150 | G40: 98 | H40: 117 | I40: 91 | J40: 150 | K40: 200 | L40: 250 | M40: 300 | O40: =SUM(B40:M40) -> 1832 | P40: =O40/12 -> 152.66667 | Q40: Normaal gemiddelde | R40: =P40 -> 152.66667 | S40: =R40*C2 -> 43.543587
A41: totaal Kwh | B41: =SUM(B39:B40) -> 451 | C41: =SUM(C39:C40) -> 384 | D41: =SUM(D39:D40) -> 397 | E41: =SUM(E39:E40) -> 346 | F41: =SUM(F39:F40) -> 360 | G41: =SUM(G39:G40) -> 335 | H41: =SUM(H39:H40) -> 315 | I41: =SUM(I39:I40) -> 281 | ... M41: =SUM(M39:M40) -> 530 | O41: =SUM(F41:M41) -> 3051 | P41: =O41/12 -> 254.25 | Q41: Totaal | R41: =SUM(R39:R40) -> 385.75 | S41: =SUM(S39:S40) -> 100.21314
A42: Gas | B42: 261 | C42: 149 | D42: 95 | E42: 36 | F42: 23 | G42: 21 | H42: 20 | I42: 30 | J42: 40 | K42: 50 | L42: 50 | M42: 50 | O42: =SUM(B42:M42) -> 825 | P42: =O42/12 -> 68.75 | Q42: Gas per jaar | R42: =P42 -> 68.75 | S42: =R42*C28 -> 88.080437
...

Sheet Loonstijging 2021-2030
A2: maand | B2: inkomen | C2: opmerking | D2: werkgever | F2: Jaren | G2: Totaal | H2: Gemiddeld per maand | I2: groei in % | J2: kosten | K2: extra inkomsten | L2: totaal inkomsten per maand
A3: 43101 | B3: 1200 | D3: Duo & Notable IT | F3: 2018 | G3: =SUM(B3:B14) -> 19200 | H3: =G3/12 -> 1600 | I3: 100 | J3: =$G78 -> 3922.46 | K3: 0 | L3: =H3+K3 -> 1600
A4: 43132 | B4: 1200 | D4: Duo & Notable IT | F4: 2019 | G4: =SUM(B15:B26) -> 22300 | H4: =G4/12 -> 1858.3333 | I4: =(H4/H3*100)-100 -> 16.145833 | J4: =G78 -> 3922.46 | K4: 0 | L4: =H4+K4 -> 1858.3333
A5: 43160 | B5: 1200 | D5: Duo & Notable IT | F5: 2020 | G5: =SUM(B27:B38) -> 25600 | H5: =G5/12 -> 2133.3333 | I5: =(H5/H4*100)-100 -> 14.798206 | J5: =G78 -> 3922.46 | K5: 0 | L5: =H5+K5 -> 2133.3333
A6: 43191 | B6: 1200 | D6: Duo & Notable IT | F6: 2021 | G6: =SUM(B39:B50) -> 30471 | H6: =G6/12 -> 2539.25 | I6: =(H6/H5*100)-100 -> 19.027344 | J6: =G78 -> 3922.46 | K6: 0 | L6: =H6+K6 -> 2539.25
A7: 43221 | B7: 1800 | D7: Southernhill | F7: 2022 | G7: =SUM(B51:B62) -> 34615 | H7: =G7/12 -> 2884.5833 | I7: =(H7/H6*100)-100 -> 13.599816 | J7: =G78 -> 3922.46 | K7: 0 | L7: =H7+K7 -> 2884.5833
A8: 43252 | B8: 1800 | D8: Southernhill | F8: 2023 | G8: =SUM(B63:B74) -> 41982 | H8: =G8/12 -> 3498.5 | I8: =(H8/H7*100)-100 -> 21.282681 | J8: =G78 -> 3922.46 | K8: 0 | L8: =H8+K8 -> 3498.5
A9: 43282 | B9: 1800 | D9: Southernhill | F9: 2024 | G9: =SUM(B75:B86) -> 45123 | H9: =G9/12 -> 3760.25 | I9: =(H9/H8*100)-100 -> 7.4817779 | J9: =G78 -> 3922.46 | K9: 0 | L9: =H9+K9 -> 3760.25
A10: 43313 | B10: 1800 | D10: Southernhill | F10: 2025 | G10: =SUM(B87:B98) -> 47024 | H10: =G10/12 -> 3918.6667 | I10: =(H10/H9*100)-100 -> 4.2129291 | J10: =G78 -> 3922.46 | K10: 250 | L10: =H10+K10 -> 4168.6667
A11: 43344 | B11: 1800 | D11: Southernhill | F11: 2026 | G11: =SUM(B99:B110) -> 48830 | H11: =G11/12 -> 4069.1667 | I11: =(H11/H10*100)-100 -> 3.840592 | J11: =G78 -> 3922.46 | K11: 250 | L11: =H11+K11 -> 4319.1667
A12: 43374 | B12: 1800 | D12: Southernhill | F12: 2027 | G12: =SUM(B111:B122) -> 50310 | H12: =G12/12 -> 4192.5 | I12: =(H12/H11*100)-100 -> 3.0309236 | J12: =G78 -> 3922.46 | K12: 250 | L12: =H12+K12 -> 4442.5
A13: 43405 | B13: 1800 | D13: Southernhill | F13: 2028 | G13: =SUM(B123:B134) -> 51820 | H13: =G13/12 -> 4318.3333 | I13: =(H13/H12*100)-100 -> 3.0013914 | J13: =G78 -> 3922.46 | K13: 250 | L13: =H13+K13 -> 4568.3333
A14: 43435 | B14: 1800 | D14: Southernhill | F14: 2029 | G14: =SUM(B135:B146) -> 52974 | H14: =G14/12 -> 4414.5 | I14: =(H14/H13*100)-100 -> 2.2269394 | J14: =G78 -> 3922.46 | K14: 250 | L14: =H14+K14 -> 4664.5
A15: 43466 | B15: 1800 | D15: Southernhill | F15: 2030 | G15: =SUM(B147:B158) -> 53783 | H15: =G15/12 -> 4481.9167 | I15: =(H15/H14*100)-100 -> 1.5271643 | J15: =G78 -> 3922.46 | K15: 250 | L15: =H15+K15 -> 4731.9167
A16: 43497 | B16: 1800 | D16: Southernhill
A17: 43525 | B17: 1800 | D17: Southernhill
A18: 43556 | B18: 1800 | D18: Southernhill
A19: 43586 | B19: 2500 | C19: vakantiegeld | D19: Southernhill | K19: Salaris schaal | L19: 3847
A20: 43617 | B20: 1800 | D20: Southernhill | L20: 5913
A21: 43647 | B21: 1800 | D21: Southernhill | K21: functiematrix | L21: schaal 10
A22: 43678 | B22: 1800 | D22: Southernhill
A23: 43709 | B23: 1800 | D23: Southernhill
A24: 43739 | B24: 1800 | D24: Southernhill
A25: 43770 | B25: 1800 | D25: Southernhill
A26: 43800 | B26: 1800 | D26: Southernhill
A27: 43831 | B27: 2000 | D27: Southernhill
A28: 43862 | B28: 2000 | D28: Southernhill | F28: Jaren | H28: Bedrag per maand | I28: Maanden | J28: Totaal | K28: 51000 | L28: Sparen | M28: Schuld K.K | N28: Maanden | O28: Totaal | P28: 13500 | Q28: Totaal sparen | R28: Totaal per maand betalen
A29: 43891 | B29: 2000 | D29: Southernhill | F29: 1 | G29: 2026 | H29: 700 | I29: 12 | J29: =H29*I29 -> 8400 | K29: =K28-J29 -> 42600 | L29: 50 | M29: 224 | N29: 12 | O29: =M29*N29 -> 2688 | P29: =P28-O29 -> 10812 | Q29: =L29*N29 -> 600 | R29: =H29+L29+M29 -> 974
A30: 43922 | B30: 2000 | D30: Southernhill | F30: 2 | G30: 2027 | H30: 1000 | I30: 12 | J30: =H30*I30 -> 12000 | K30: =K29-J30 -> 30600 | L30: 50 | M30: 224 | N30: 12 | O30: =M30*N30 -> 2688 | P30: =P29-O30 -> 8124 | Q30: =L30*N30 -> 600 | R30: =H30+L30+M30 -> 1274
A31: 43952 | B31: 3000 | C31: Vakantie geld | D31: Southernhill | F31: 3 | G31: 2028 | H31: 1000 | I31: 12 | J31: =H31*I31 -> 12000 | K31: =K30-J31 -> 18600 | L31: 50 | M31: 224 | N31: 12 | O31: =M31*N31 -> 2688 | P31: =P30-O31 -> 5436 | Q31: =L31*N31 -> 600 | R31: =H31+L31+M31 -> 1274
A32: 43983 | B32: 2000 | D32: Southernhill | F32: 4 | G32: 2029 | H32: 1000 | I32: 12 | J32: =H32*I32 -> 12000 | K32: =K31-J32 -> 6600 | L32: 50 | M32: 224 | N32: 12 | O32: =M32*N32 -> 2688 | P32: =P31-O32 -> 2748 | Q32: =L32*N32 -> 600 | R32: =H32+L32+M32 -> 1274
A33: 44013 | B33: 2000 | D33: Southernhill | F33: 5 | G33: 2030 | H33: 550 | I33: 12 | J33: =H33*I33 -> 6600 | K33: =K32-J33 -> 0 | L33: 750 | M33: 229 | N33: 12 | O33: =M33*N33 -> 2748 | P33: =P32-O33 -> 0 | Q33: =L33*N33 -> 9000 | R33: =H33+L33+M33 -> 1529
A34: 44044 | B34: 2000 | D34: Southernhill | F34: 6 | G34: 2031 | H34: 0 | I34: 0 | J34: =H34*I34 -> 0 | K34: =K33-J34 -> 0 | L34: 750 | M34: 0 | N34: 12 | O34: =M34*N34 -> 0 | P34: =P33-O34 -> 0 | Q34: =L34*N34 -> 9000 | R34: =H34+L34+M34 -> 750
A35: 44075 | B35: 2000 | D35: Southernhill | F35: 7 | G35: 2032 | H35: 0 | I35: 0 | J35: =H35*I35 -> 0 | K35: =K34-J35 -> 0 | L35: 750 | M35: 0 | N35: 12 | O35: =M35*N35 -> 0 | P35: =P34-O35 -> 0 | Q35: =L35*N35 -> 9000 | R35: =H35+L35+M35 -> 750
A36: 44105 | B36: 2200 | D36: Zuyd | F36: 8 | G36: 2033 | H36: 0 | I36: 0 | J36: =H36*I36 -> 0 | K36: =K35-J36 -> 0 | L36: 750 | M36: 0 | N36: 12 | O36: =M36*N36 -> 0 | P36: =P35-O36 -> 0 | Q36: =L36*N36 -> 9000 | R36: =H36+L36+M36 -> 750
A37: 44136 | B37: 2200 | D37: Zuyd | F37: 9 | G37: 2034 | H37: 0 | I37: 0 | J37: 0 | K37: 0 | L37: 750 | M37: 0 | N37: 12 | O37: =M37*N37 -> 0 | P37: =P36-O37 -> 0 | Q37: =L37*N37 -> 9000 | R37: =H37+L37+M37 -> 750
A38: 44166 | B38: 2200 | D38: Zuyd | F38: 10 | G38: 2035 | H38: 0 | I38: 0 | J38: 0 | K38: 0 | L38: 750 | M38: 0 | N38: 12 | O38: =M38*N38 -> 0 | P38: =P37-O38 -> 0 | Q38: =L38*N38 -> 9000 | R38: =H38+L38+M38 -> 750
A39: 44197 | B39: 2302 | D39: Zuyd | F39: 11 | G39: 2036 | H39: 0 | I39: 0 | J39: 0 | K39: 0 | L39: 750 | M39: 0 | N39: 12 | O39: =M39*N39 -> 0 | P39: =P38-O39 -> 0 | Q39: =L39*N39 -> 9000 | R39: =H39+L39+M39 -> 750
A40: 44228 | B40: 2302 | D40: Zuyd | F40: 12 | G40: 2037 | H40: 0 | I40: 0 | J40: 0 | K40: 0 | L40: 750 | M40: 0 | N40: 12 | O40: =M40*N40 -> 0 | P40: =P39-O40 -> 0 | Q40: =L40*N40 -> 9000 | R40: =H40+L40+M40 -> 750
A41: 44256 | B41: 2302 | D41: Zuyd | F41: 13 | G41: 2038 | H41: 0 | I41: 0 | J41: 0 | K41: 0 | M41: 0 | N41: 12 | O41: =M41*N41 -> 0 | P41: =P40-O41 -> 0 | Q41: =L41*N41 -> 0 | R41: =H41+L41+M41 -> 0
...

Sheet Grafieken

Sheet extra hypotheek
A1: inkomsten krien | C1: inkomsten josh | E1: uitgaves josh | G1: Gezamelijke inkomsten | I1: gedeelde uitgaves
A2: Loon | B2: 0 | C2: loon | D2: 3740 | E2: boogschieten | F2: 10 | G2: huurtoeslag | H2: 0 | I2: hypotheek | J2: 1256.09 | M2: kinder gebonden budget
A3: spaargeld | B3: 0 | C3: hypo-aftrek | D3: 568 | E3: scouting | F3: 10 | G3: kinderbijslag | H3: 0 | I3: gas elec | J3: =114+73 -> 187 | M3: 1 kind op mijn naam met kinderbijslag
C4: loonverhoging | E4: Schenking | F4: 224.2 | G4: zorgtoeslag | H4: 0 | I4: water | J4: 42.5 | L4: sem | M4: 259
C5: loonverhoging2 % | E5: alimentatie | F5: 420 | G5: kinder geb budget | H5: 0 | I5: bsgw | J5: 33.76 | L5: lucas | M5: 200
C6: afbetaling krien | D6: 0 | I6: ziggo | J6: 60 | L6: sophie | M6: 200
I7: NN pakketverzekering Confident limburg | J7: 72.66
I8: vodafoon | J8: 39.24 | M8: kinder gebonden budget
I9: NN | J9: 184.78 | M9: 2 kind op mijn naam met kinderbijslag
I10: auto verzek | J10: 40 | L10: sem | M10: 468
I11: wegenbelasting | J11: 70 | L11: lucas | M11: 468
I12: dela | J12: 10.93 | L12: sophie | M12: 200
I13: TAF | J13: 32
A15: totalen | B15: =SUM(B2:B14) -> 0 | C15: totaal | D15: =SUM(D2:D14) -> 4308 | E15: totaal | F15: =SUM(F2:F14) -> 664.2 | G15: totaal toeslagen | H15: =H2+H3+H4+H5+H6+H7+H8 -> 0 | I15: tvabbo | J15: 22
A17: totalen netto inkomsten | C17: =D15 -> 4308 | D17: =(D15*1.02)+125 -> 4519.16 | E17: =(D17*1.02)+125 -> 4734.5432
A19: totaal uitgaves | C19: =F15+J36+J22 -> 4086.66 | D19: =F15+J36+J22 -> 4086.66 | E19: =F15+J36+J22 -> 4086.66 | L19: 40
L20: 70
A21: totaal over te spenderen | C21: =C17-C19 -> 221.34 | D21: =D17-D19 -> 432.5 | E21: =E17-E19 -> 647.8832 | G21: voorlopige aanslag 2025 | H21: 8774
I22: subtotaal | J22: =SUM(J2:J21) -> 2050.96
A24: bruto | C24: 6219 | D24: 6343.38 | E24: 6470.2 | I24: hond eten | J24: 80
A25: netto | C25: =3537.99 -> 3537.99 | D25: =D17 -> 4519.16 | E25: =E17 -> 4734.5432 | I25: Benzine | J25: 0
A26: verschil bruto - netto | C26: =C24-C25 -> 2681.01 | D26: =D24-D25 -> 1824.22 | E26: =E24-E25 -> 1735.6568 | I26: eten | J26: 600
A27: vakantiegeld netto | C27: 2539.41 | D27: 2700 | E27: 2900
A28: bruto verschil met huidige loon | D28: =D25-$C25 -> 981.17 | E28: =E25-$D25 -> 215.3832
A29: hypo aftrek | C29: =D3 -> 568 | D29: =D3 -> 568 | E29: =D3 -> 568 | K29: 214 | L29: 3
A30: eenmalige ontvangsten | C30: 1000 | D30: 1000 | E30: 1000 | I30: sparen kids | J30: =6.5+5+5 -> 16.5
A31: Bijtelling leaseauto | C31: 605 | D31: 605 | E31: 605 | I31: sparen noodpotje
A32: jaarbasis | C32: 77550 | D32: 79101 | E32: 80683.02 | I32: DUO afbetaling | J32: 500 | K32: 500
A33: loonheffingsloon | C33: 25708 | D33: 26221 | E33: 26746
A34: toestingsinkomen | C34: =C32 -> 77550 | D34: =D32 -> 79101 | E34: =E32 -> 80683.02 | I34: Warmtefonds volle pond | J34: 175 | K34: ='[1]JB 2025 December'!$J$34 -> 384.31667
A35: hypotheek per maand | C35: =(J2*12)-(C29*12) -> 8257.08 | D35: =J2*12 -> 15073.08 | E35: =J2*12 -> 15073.08
A36: Netto per jaar | C36: =C32-C33 -> 51842 | D36: =D32-D33 -> 52880 | E36: =E32-E33 -> 53937.02 | I36: subtotaal | J36: =SUM(J24:J35) -> 1371.5
I37: Totaal | J37: =J22+J36 -> 3422.46
A40: Vloerverwarming | C40: 7000
A41: Ramen | B41: 23000
A42: muur isolatie | B42: 3500 | C42: 60m2+24m2+24M2
A43: impregneren | B43: 1500
A54: totaal | B54: =SUM(B40:B52) -> 28000

Sheet Basistabel hoger loon
A1: inkomsten krien | C1: inkomsten josh | E1: uitgaves josh | G1: Gezamelijke inkomsten | I1: gedeelde uitgaves
A2: Loon | B2: 0 | C2: loon | D2: 3840 | E2: boogschieten | F2: 10 | G2: huurtoeslag | H2: 0 | I2: hypotheek | J2: 1256.09 | M2: kinder gebonden budget
A3: spaargeld | B3: 0 | C3: hypo-aftrek | D3: 568 | E3: scouting | F3: 10 | G3: kinderbijslag | H3: 0 | I3: gas elec | J3: 155 | M3: 1 kind op mijn naam met kinderbijslag
C4: loonverhoging | E4: Schenking | F4: 224.2 | G4: zorgtoeslag | H4: 0 | I4: water | J4: 42.5 | L4: sem | M4: 259
C5: loonverhoging2 % | E5: alimentatie | F5: 420 | G5: kinder geb budget | H5: 0 | I5: bsgw | J5: 33.76 | L5: lucas | M5: 200
C6: afbetaling krien | D6: 0 | I6: ziggo | J6: 60 | L6: sophie | M6: 200
I7: NN pakketverzekering Confident limburg | J7: 72.66
I8: vodafoon | J8: 39.24 | M8: kinder gebonden budget
I9: NN | J9: 184.78 | M9: 2 kind op mijn naam met kinderbijslag
I10: auto verzek | J10: 40 | L10: sem | M10: 468
I11: wegenbelasting | J11: 70 | L11: lucas | M11: 468
I12: dela | J12: 10.93 | L12: sophie | M12: 200
I13: TAF | J13: 32
A15: totalen | B15: =SUM(B2:B14) -> 0 | C15: totaal | D15: =SUM(D2:D14) -> 4408 | E15: totaal | F15: =SUM(F2:F14) -> 664.2 | G15: totaal toeslagen | H15: =H2+H3+H4+H5+H6+H7+H8 -> 0 | I15: tvabbo | J15: 22
J16: 180
A17: totalen netto inkomsten | C17: =D15 -> 4408 | D17: =(D15*1.02)+125 -> 4621.16 | E17: =(D17*1.02)+125 -> 4838.5832
A19: totaal uitgaves | C19: =F15+J36+J22 -> 3784.66 | D19: =F15+J36+J22 -> 3784.66 | E19: =F15+J36+J22 -> 3784.66 | L19: 40
L20: 70
A21: totaal over te spenderen | C21: =C17-C19 -> 623.34 | D21: =D17-D19 -> 836.5 | E21: =E17-E19 -> 1053.9232 | G21: voorlopige aanslag 2025 | H21: 8774
I22: subtotaal | J22: =SUM(J2:J21) -> 2198.96
A24: bruto | C24: 6219 | D24: 6343.38 | E24: 6470.2 | I24: hond eten | J24: 80 | L24: Bruto | M24: Bruto hoogste laagste | N24: Netto | O24: Netto geschat | P24: verschil cumulatief van stap eerder | Q24: verschil hoogste laagste
A25: netto | C25: =3537.99 -> 3537.99 | D25: =D17 -> 4621.16 | E25: =E17 -> 4838.5832 | I25: Benzine | J25: 0 | L25: 5851 | M25: =L25-L25 -> 0 | N25: 3730 | O25: =N25 -> 3730 | P25: =N25-N25 -> 0 | Q25: 0
A26: verschil bruto - netto | C26: =C24-C25 -> 2681.01 | D26: =D24-D25 -> 1722.22 | E26: =E24-E25 -> 1631.6168 | I26: eten | J26: 600 | L26: 5963 | M26: =L26-L25 -> 112 | N26: 3819 | O26: =N26 -> 3819 | P26: =N26-N25 -> 89 | Q26: =N26-N25 -> 89
A27: vakantiegeld netto | C27: 2539.41 | D27: 2700 | E27: 2900 | L27: 6500 | M27: =L27-L26 -> 537 | N27: 4151 | O27: =N27-50 -> 4101 | P27: =N27-N26 -> 332 | Q27: =N27-N26 -> 332
A28: bruto verschil met huidige loon | D28: =D25-$C25 -> 1083.17 | E28: =E25-$D25 -> 217.4232 | L28: 7000 | M28: =L28-L26 -> 1037 | N28: 4369 | O28: =N28-70 -> 4299 | P28: =N28-N27 -> 218 | Q28: =N28-N26 -> 550
A29: hypo aftrek | C29: =D3 -> 568 | D29: =D3 -> 568 | E29: =D3 -> 568 | J29: 225 | K29: 214 | L29: 7500 | M29: =L29-L26 -> 1537 | N29: 4589 | O29: =N29-100 -> 4489 | P29: =N29-N28 -> 220 | Q29: =N29-N26 -> 770
A30: eenmalige ontvangsten | C30: 1000 | D30: 1000 | E30: 1000 | I30: sparen kids | J30: =6.5+5+5 -> 16.5
A31: Bijtelling leaseauto | C31: 605 | D31: 605 | E31: 605 | I31: sparen noodpotje
A32: jaarbasis | C32: 77550 | D32: 79101 | E32: 80683.02 | I32: DUO afbetaling | K32: 500
A33: loonheffingsloon | C33: 25708 | D33: 26221 | E33: 26746
A34: toestingsinkomen | C34: =C32 -> 77550 | D34: =D32 -> 79101 | E34: =E32 -> 80683.02 | K34: ='[1]JB 2025 December'!$J$34 -> 384.31667
A35: hypotheek per maand | C35: =(J2*12)-(C29*12) -> 8257.08 | D35: =J2*12 -> 15073.08 | E35: =J2*12 -> 15073.08
A36: Netto per jaar | C36: =C32-C33 -> 51842 | D36: =D32-D33 -> 52880 | E36: =E32-E33 -> 53937.02 | I36: subtotaal | J36: =SUM(J24:J35) -> 921.5
I37: Totaal | J37: =J22+J36 -> 3120.46
A40: bruto | B40: =C24 -> 6219
A41: netto | B41: =C24*0.5998 -> 3730.1562
A42: verschil bruto - netto | B42: =B40-B41 -> 2488.8438
A43: vakantiegeld | B43: =((B40-B47)*12)/100*8 -> 5389.44
A44: verschil met huidige loon | B44: =C25-B25 -> 3537.99
A45: Totaal over na onkosten | B45: =C29 -> 568
...

Sheet Basistabel
A1: inkomsten krien | C1: inkomsten josh | E1: uitgaves josh | G1: Gezamelijke inkomsten | I1: gedeelde uitgaves
A2: Loon | B2: 0 | C2: loon | D2: 3840 | E2: boogschieten | F2: 10 | G2: huurtoeslag | H2: 0 | I2: hypotheek | J2: 1256.09 | M2: kinder gebonden budget
A3: spaargeld | B3: 0 | C3: hypo-aftrek | D3: 568 | E3: scouting | F3: 10 | G3: kinderbijslag | H3: 0 | I3: gas elec | J3: =150+100 -> 250 | K3: =J3-J18 -> 110 | M3: 1 kind op mijn naam met kinderbijslag
C4: loonverhoging | E4: Schenking | F4: 224.2 | G4: zorgtoeslag | H4: 0 | I4: water | J4: 42.5 | L4: sem | M4: 259
C5: loonverhoging2 % | E5: alimentatie | F5: 420 | G5: kinder geb budget | H5: 0 | I5: bsgw | J5: 33.76 | L5: lucas | M5: 200
C6: afbetaling krien | D6: 0 | I6: ziggo | J6: 60 | L6: sophie | M6: 200
I7: NN pakketverzekering Confident limburg | J7: 72.66
I8: vodafoon | J8: 39.24 | M8: kinder gebonden budget
I9: NN | J9: 184.78 | M9: 2 kind op mijn naam met kinderbijslag
I10: auto verzek | J10: 40 | L10: sem | M10: 468
I11: wegenbelasting | J11: 70 | L11: lucas | M11: 468
I12: dela | J12: 10.93 | L12: sophie | M12: 200
I13: TAF | J13: 32
A15: totalen | B15: =SUM(B2:B14) -> 0 | C15: totaal | D15: =SUM(D2:D14) -> 4408 | E15: totaal | F15: =SUM(F2:F14) -> 664.2 | G15: totaal toeslagen | H15: =H2+H3+H4+H5+H6+H7+H8 -> 0 | I15: tvabbo | J15: 22 | M15: =J2+J7 -> 1328.75
A17: totalen netto inkomsten | C17: =D15 -> 4408 | D17: =(D15*1.02)+125 -> 4621.16 | E17: =(D17*1.02)+125 -> 4838.5832 | I17: warmtefonds | J17: =Offertes!M29 -> 156.45 | K17: =J17-J18 -> 16.45
I18: energie besparing | J18: =Offertes!C44 -> 140
A19: totaal uitgaves | C19: =F15+J36+J22 -> 3571.11 | D19: =F15+J36+J22 -> 3571.11 | E19: =F15+J36+J22 -> 3571.11 | L19: 40
L20: 70
A21: totaal over te spenderen | C21: =C17-C19 -> 836.89 | D21: =D17-D19 -> 1050.05 | E21: =E17-E19 -> 1267.4732 | G21: voorlopige aanslag 2025 | H21: 8774
I22: subtotaal | J22: =SUM(J2:J21) -> 2410.41
A24: bruto | C24: 6219 | D24: 6343.38 | E24: 6470.2 | I24: hond eten | J24: 80 | M24: gas | N24: 148
A25: netto | C25: =3537.99 -> 3537.99 | D25: =D17 -> 4621.16 | E25: =E17 -> 4838.5832 | I25: Benzine | J25: 0 | M25: elec | N25: 85
A26: verschil bruto - netto | C26: =C24-C25 -> 2681.01 | D26: =D24-D25 -> 1722.22 | E26: =E24-E25 -> 1631.6168 | I26: eten | J26: 400
A27: vakantiegeld netto | C27: 2539.41 | D27: 2700 | E27: 2900
A28: bruto verschil met huidige loon | D28: =D25-$C25 -> 1083.17 | E28: =E25-$D25 -> 217.4232
A29: hypo aftrek | C29: =D3 -> 568 | D29: =D3 -> 568 | E29: =D3 -> 568 | K29: 214 | L29: 3
A30: eenmalige ontvangsten | C30: 1000 | D30: 1000 | E30: 1000 | I30: sparen kids | J30: =6.5+5+5 -> 16.5
A31: Bijtelling leaseauto | C31: 605 | D31: 605 | E31: 605 | I31: sparen noodpotje
A32: jaarbasis | C32: 77550 | D32: 79101 | E32: 80683.02 | I32: DUO afbetaling | K32: 500
A33: loonheffingsloon | C33: 25708 | D33: 26221 | E33: 26746
A34: toestingsinkomen | C34: =C32 -> 77550 | D34: =D32 -> 79101 | E34: =E32 -> 80683.02 | K34: ='[1]JB 2025 December'!$J$34 -> 384.31667
A35: hypotheek per maand | C35: =(J2*12)-(C29*12) -> 8257.08 | D35: =J2*12 -> 15073.08 | E35: =J2*12 -> 15073.08
A36: Netto per jaar | C36: =C32-C33 -> 51842 | D36: =D32-D33 -> 52880 | E36: =E32-E33 -> 53937.02 | I36: subtotaal | J36: =SUM(J24:J35) -> 496.5
I37: Totaal | J37: =J22+J36 -> 2906.91
A40: bruto | B40: =C24 -> 6219
A41: netto | B41: =C24*0.5998 -> 3730.1562
A42: verschil bruto - netto | B42: =B40-B41 -> 2488.8438
A43: vakantiegeld | B43: =((B40-B47)*12)/100*8 -> 5389.44
A44: verschil met huidige loon | B44: =C25-B25 -> 3537.99
A45: Totaal over na onkosten | B45: =C29 -> 568
...

Sheet Zonneplan berekeningen
A1: Uitgaves | B1: prijs | C1: besparing
A2: gas | B2: 148
A3: elec | B3: 87
A6: lening warmte fonds | B6: 137
A7: Totaal | B7: =SUM(B2:B6) -> 372 | C7: =B7-B13 -> 161.85
A9: Vermindering elektra kosten (zonnepanelen + batterij) | B9: 104.4
A10: Dynamische handelswinsten thuisbatterij | B10: 46.72
A11: Besparing op gas met de hybride warmtepomp | B11: 59.03
A13: totaal | B13: =SUM(B9:B11) -> 210.15
A20: Subsidie spauwmuur per m2 | B20: 5.25
A21: M2 spauwmuur isolatie | B21: 85
A22: totaal | B22: =B20*B21 -> 446.25

Sheet Offertes
A1: bedrijf | B1: omschrijving | C1: subsidie | D1: prijs | E1: per maand | F1: ISDE | G1: netto | J1: Beste van alles | M1: warmtefonds | N1: 29000
A2: Isolatie broeders | B2: spauwmuur isolatie schuim | C2: ja | D2: 2200 | J2: Isotech | K2: =G9 -> 6117.41 | M2: Over: | N2: =N1-K6 -> 5180.59
A3: Zon-X | B3: Panelen, hybride warmtepomp, full elec pomp | C3: ja | D3: ? | J3: Zon-X panelen | K3: =D4 -> 7331
A4: Zon-X | B4: Panelen +meterkast | D4: 7331 | E4: 54.78 | J4: Zon-X batterij | K4: =D7 -> 6292
A5: Zon-X | B5: warmtepomp DUO | D5: 9524 | E5: 71 | J5: Zonneplan panelen | K5: 4079
A6: Zon-X | B6: warmtepomp Single | D6: 6799 | E6: 50.8 | J6: Totaal | K6: =SUM(K2:K5) -> 23819.41
A7: Zon-X | B7: batterij | D7: 6292 | E7: 47.02
L8: bruto | M8: netto
A9: Isotech maastricht | B9: Spauwmuur leeghalen en vullen | D9: 7009.91 | F9: 892.5 | G9: =D9-F9 -> 6117.41 | J9: Reinas | K9: panelen + meterkast | L9: 6300 | M9: =L9-L34 -> 2300
J10: Reinas | K10: spauwmuur | L10: 2178 | M10: =L10-L33 -> 1338
J11: Reinas | K11: kozijnen | L11: 27921.7 | M11: =L11-L32 -> 20373.7
A12: zonneplan | B12: alleen panelen | D12: 4079 | J12: TOTAAL | L12: =SUM(L9:L11) -> 36399.7 | M12: =L12-L35 -> 24011.7
A13: Zonneplan | B13: panelen met batterij + meterkast | D13: =8434.29 + 900 -> 9334.29
L14: bruto | M14: netto
J15: maat verduurzaming isolatie | K15: Zonnepanelen | L15: 5590 | M15: =L15 -> 5590 | N15: 250
A16: M2 glas | J16: maat verduurzaming isolatie | K16: Spauwmuur | L16: 2220.9 | M16: =L16-L33 -> 1380.9
A17: voorraam | B17: =3.1*1.6 -> 4.96 | J17: maat verduurzaming isolatie | K17: Kozijnen | L17: 30675.74 | M17: =L17-L32 -> 23127.74 | N17: 30676
A18: Schuifpui | B18: =4.2*2.8 -> 11.76 | D18: netto | E18: besparing | F18: nieuw netto | J18: maat verduurzaming isolatie | K18: spauw leegmaken
A19: Voordeur | B19: =2*2 -> 4 | C19: gas | D19: 150 | E19: =D19/100*75 -> 112.5 | F19: =D19-E19 -> 37.5 | K19: Totaal | L19: =SUM(L15:L18) -> 38486.64 | M19: =L19-L35 -> 26098.64 | N19: =SUM(L17,L16) -> 32896.64
A20: achterdeur beneden | B20: =2*1 -> 2
A21: Achterraam boven | B21: =2*1.3 -> 2.6 | L21: Bruto | M21: Netto
A22: Voorramen boven | B22: =1+2 -> 3 | J22: Mega verduurzaming | K22: Panelen +meterkast | L22: 5210 | M22: =L22-L34 -> 1210
A23: Totaal | B23: =SUM(B17:B22) -> 28.32 | J23: Mega verduurzaming | K23: Spauwmuur | L23: 2653 | M23: =L23-L33 -> 1813
J24: Mega verduurzaming | K24: kozijnen | L24: 29647 | M24: =L24-L32 -> 22099
K25: Totaal | L25: =SUM(L22:L24) -> 37510 | M25: =L25-L35 -> 25122
A27: Subsidie | J27: Bosch tronig 2102T 150 liter | L27: 1124
A28: Spauwmuur | B28: 892.5 | C28: quat single | D28: single | E28: 5072
A29: Kozijnen | B29: 1844 | C29: gemiddelde | D29: warmtepomp | E29: 6000 | J29: Lening Reina's | L29: =M12+L27 -> 25135.7 | M29: 156.45
A30: Wamtepomp | B30: 2800
K31: wamtefonds: | L31: 29000
A32: Totaal | B32: =SUM(B28:B30) -> 5536.5 | K32: glas | L32: 7548
K33: spauw | L33: 840
K34: gem heerlen | L34: 4000
B35: =1080/12 -> 90 | K35: subtotaal | L35: =SUM(L32:L34) -> 12388
B36: =1235/12 -> 102.91667 | K36: warmtebatterij | L36: 725
K37: Totaal | L37: =SUM(L31:L34) -> 41388
A38: Nieuwe stroom kosten | B38: 540 | C38: =B38/12 -> 45
A39: nieuwe gas kosten | B39: 300 | C39: =B39/12+40 -> 65
A42: totaal | C42: =SUM(C38:C41) -> 110
A44: beparing | B44: 250 | C44: =B44-C42 -> 140
...

Sheet januari
A1: inkomsten krien | C1: inkomsten josh | E1: uitgaves josh | G1: Gezamelijke inkomsten | I1: gedeelde uitgaves
A2: Loon | B2: 0 | C2: loon | D2: =3740+800 -> 4540 | E2: boogschieten | F2: 10 | G2: huurtoeslag | H2: 0 | I2: hypotheek | J2: 1256.09 | M2: kinder gebonden budget
A3: spaargeld | B3: 0 | C3: hypo-aftrek | D3: 568 | E3: scouting | F3: 10 | G3: kinderbijslag | H3: 0 | I3: gas elec | J3: =Basistabel!J3 -> 250 | M3: 1 kind op mijn naam met kinderbijslag
C4: loonverhoging | E4: Schenking | F4: 224.2 | G4: zorgtoeslag | H4: 0 | I4: water | J4: 42.5 | L4: sem | M4: 259
C5: loonverhoging2 % | E5: alimentatie | F5: 420 | G5: kinder geb budget | H5: 0 | I5: bsgw | J5: 33.76 | L5: lucas | M5: 200
C6: afbetaling krien | D6: 0 | I6: ziggo | J6: 60 | L6: sophie | M6: 200
I7: NN pakketverzekering Confident limburg | J7: 72.66
I8: vodafoon | J8: 39.24 | M8: kinder gebonden budget
I9: NN | J9: 184.78 | M9: 2 kind op mijn naam met kinderbijslag
I10: auto verzek | J10: 40 | L10: sem | M10: 468
I11: wegenbelasting | J11: 70 | L11: lucas | M11: 468
I12: dela | J12: 10.93 | L12: sophie | M12: 200
I13: TAF | J13: 32
A15: totalen | B15: =SUM(B2:B14) -> 0 | C15: totaal | D15: =SUM(D2:D14) -> 5108 | E15: totaal | F15: =SUM(F2:F14) -> 664.2 | G15: totaal toeslagen | H15: =H2+H3+H4+H5+H6+H7+H8 -> 0 | I15: tvabbo | J15: 22
I16: bril | J16: 77
A17: totalen netto inkomsten | C17: =D15 -> 5108 | D17: =(D15*1.02)+125 -> 5335.16 | E17: =(D17*1.02)+125 -> 5566.8632 | I17: pc | J17: =663+55 -> 718
I18: extra | J18: 184.78
A19: totaal uitgaves | C19: =F15+J36+J22 -> 5257.44 | D19: =F15+J36+J22 -> 5257.44 | E19: =F15+J36+J22 -> 5257.44 | I19: energie | J19: =2*117 -> 234
I20: drinkbak | J20: 69
A21: totaal over te spenderen | C21: =C17-C19 -> -149.44 | D21: =D17-D19 -> 77.72 | E21: =E17-E19 -> 309.4232 | G21: voorlopige aanslag 2025 | H21: 8774 | I21: penning kapper | J21: =22+30+78+25+56+100+15+76+65+33 -> 500
I22: subtotaal | J22: =SUM(J2:J21) -> 3896.74
A24: bruto | C24: 6219 | D24: 6343.38 | E24: 6470.2 | I24: hond eten | J24: 80
A25: netto | C25: =3537.99 -> 3537.99 | D25: =D17 -> 5335.16 | E25: =E17 -> 5566.8632 | I25: Benzine | J25: 0
A26: verschil bruto - netto | C26: =C24-C25 -> 2681.01 | D26: =D24-D25 -> 1008.22 | E26: =E24-E25 -> 903.3368 | I26: eten | J26: 600
A27: vakantiegeld netto | C27: 2539.41 | D27: 2700 | E27: 2900
A28: bruto verschil met huidige loon | D28: =D25-$C25 -> 1797.17 | E28: =E25-$D25 -> 231.7032
A29: hypo aftrek | C29: =D3 -> 568 | D29: =D3 -> 568 | E29: =D3 -> 568 | K29: 214 | L29: 3
A30: eenmalige ontvangsten | C30: 1000 | D30: 1000 | E30: 1000 | I30: sparen kids | J30: =6.5+5+5 -> 16.5
A31: Bijtelling leaseauto | C31: 605 | D31: 605 | E31: 605 | I31: sparen noodpotje
A32: jaarbasis | C32: 77550 | D32: 79101 | E32: 80683.02 | K32: 423.51 | L32: vanaf Maart
A33: loonheffingsloon | C33: 25708 | D33: 26221 | E33: 26746
A34: toestingsinkomen | C34: =C32 -> 77550 | D34: =D32 -> 79101 | E34: =E32 -> 80683.02
A35: hypotheek per maand | C35: =(J2*12)-(C29*12) -> 8257.08 | D35: =J2*12 -> 15073.08 | E35: =J2*12 -> 15073.08
A36: Netto per jaar | C36: =C32-C33 -> 51842 | D36: =D32-D33 -> 52880 | E36: =E32-E33 -> 53937.02 | I36: subtotaal | J36: =SUM(J24:J35) -> 696.5
I37: Totaal | J37: =J22+J36 -> 4593.24
A40: bruto | B40: =C24 -> 6219
A41: netto | B41: =C24*0.5998 -> 3730.1562
A42: verschil bruto - netto | B42: =B40-B41 -> 2488.8438
A43: vakantiegeld | B43: =((B40-B47)*12)/100*8 -> 5389.44
A44: verschil met huidige loon | B44: =C25-B25 -> 3537.99
...

Sheet Februari
A1: inkomsten krien | C1: inkomsten josh | E1: uitgaves josh | G1: Gezamelijke inkomsten | I1: gedeelde uitgaves
A2: Loon | B2: 0 | C2: loon | D2: 3740 | E2: boogschieten | F2: 10 | G2: huurtoeslag | H2: 0 | I2: hypotheek | J2: 1256.09 | M2: kinder gebonden budget
A3: spaargeld | B3: 0 | C3: hypo-aftrek | D3: 568 | E3: scouting | F3: 10 | G3: kinderbijslag | H3: 0 | I3: gas elec | J3: =Basistabel!J3 -> 250 | M3: 1 kind op mijn naam met kinderbijslag
C4: loonverhoging | E4: Schenking | F4: 224.2 | G4: zorgtoeslag | H4: 0 | I4: water | J4: 42.5 | L4: sem | M4: 259
C5: loonverhoging2 % | E5: alimentatie | F5: 420 | G5: kinder geb budget | H5: 0 | I5: bsgw | J5: 33.76 | L5: lucas | M5: 200
C6: afbetaling krien | D6: 0 | I6: ziggo | J6: 60 | L6: sophie | M6: 200
I7: NN pakketverzekering Confident limburg | J7: 72.66
I8: vodafoon | J8: 39.24 | M8: kinder gebonden budget
I9: NN | J9: 184.78 | M9: 2 kind op mijn naam met kinderbijslag
I10: auto verzek | J10: 40 | L10: sem | M10: 468
I11: wegenbelasting | J11: 70 | L11: lucas | M11: 468
I12: dela | J12: 10.93 | L12: sophie | M12: 200
I13: TAF | J13: 32
I14: vgz | J14: 37.5
A15: totalen | B15: =SUM(B2:B14) -> 0 | C15: totaal | D15: =SUM(D2:D14) -> 4308 | E15: totaal | F15: =SUM(F2:F14) -> 664.2 | G15: totaal toeslagen | H15: =H2+H3+H4+H5+H6+H7+H8 -> 0 | I15: tvabbo | J15: 22
J16: 117
A17: totalen netto inkomsten | C17: =D15 -> 4308 | D17: =(D15*1.02)+125 -> 4519.16 | E17: =(D17*1.02)+125 -> 4734.5432 | J17: 40
J18: 184
A19: totaal uitgaves | C19: =F15+J36+J22 -> 4342.16 | D19: =F15+J36+J22 -> 4342.16 | E19: =F15+J36+J22 -> 4342.16 | J19: 664 | L19: 40
I20: boete | J20: 25 | L20: 70
A21: totaal over te spenderen | C21: =C17-C19 -> -34.16 | D21: =D17-D19 -> 177 | E21: =E17-E19 -> 392.3832 | G21: voorlopige aanslag 2025 | H21: 8774
I22: subtotaal | J22: =SUM(J2:J21) -> 3181.46
A24: bruto | C24: 6219 | D24: 6343.38 | E24: 6470.2 | I24: hond eten | J24: 80
A25: netto | C25: =3537.99 -> 3537.99 | D25: =D17 -> 4519.16 | E25: =E17 -> 4734.5432 | I25: Benzine | J25: 0
A26: verschil bruto - netto | C26: =C24-C25 -> 2681.01 | D26: =D24-D25 -> 1824.22 | E26: =E24-E25 -> 1735.6568 | I26: eten | J26: 400 | L26: =50+50+50+50 -> 200
A27: vakantiegeld netto | C27: 2539.41 | D27: 2700 | E27: 2900
A28: bruto verschil met huidige loon | D28: =D25-$C25 -> 981.17 | E28: =E25-$D25 -> 215.3832
A29: hypo aftrek | C29: =D3 -> 568 | D29: =D3 -> 568 | E29: =D3 -> 568 | K29: 214 | L29: 3
A30: eenmalige ontvangsten | C30: 1000 | D30: 1000 | E30: 1000 | I30: sparen kids | J30: =6.5+5+5 -> 16.5
A31: Bijtelling leaseauto | C31: 605 | D31: 605 | E31: 605 | I31: sparen noodpotje
A32: jaarbasis | C32: 77550 | D32: 79101 | E32: 80683.02 | I32: DUO afbetaling | J32: 0 | K32: 500
A33: loonheffingsloon | C33: 25708 | D33: 26221 | E33: 26746
A34: toestingsinkomen | C34: =C32 -> 77550 | D34: =D32 -> 79101 | E34: =E32 -> 80683.02 | K34: ='[1]JB 2025 December'!$J$34 -> 384.31667
A35: hypotheek per maand | C35: =(J2*12)-(C29*12) -> 8257.08 | D35: =J2*12 -> 15073.08 | E35: =J2*12 -> 15073.08
A36: Netto per jaar | C36: =C32-C33 -> 51842 | D36: =D32-D33 -> 52880 | E36: =E32-E33 -> 53937.02 | I36: subtotaal | J36: =SUM(J24:J35) -> 496.5
I37: Totaal | J37: =J22+J36 -> 3677.96
A40: bruto | B40: =C24 -> 6219
A41: netto | B41: =C24*0.5998 -> 3730.1562
A42: verschil bruto - netto | B42: =B40-B41 -> 2488.8438
A43: vakantiegeld | B43: =((B40-B47)*12)/100*8 -> 5389.44
...

Sheet Maart
A1: inkomsten krien | C1: inkomsten josh | E1: uitgaves josh | G1: Gezamelijke inkomsten | I1: gedeelde uitgaves
A2: Loon | B2: 0 | C2: loon | D2: 3740 | E2: boogschieten | F2: 10 | G2: huurtoeslag | H2: 0 | I2: hypotheek | J2: 1256.09 | M2: kinder gebonden budget
A3: spaargeld | B3: 0 | C3: hypo-aftrek | D3: 550 | E3: scouting | F3: 10 | G3: kinderbijslag | H3: 0 | I3: gas elec | J3: =Basistabel!J3 -> 250 | M3: 1 kind op mijn naam met kinderbijslag
C4: loonverhoging | E4: Schenking | F4: 224.2 | G4: zorgtoeslag | H4: 0 | I4: water | J4: 42.5 | L4: sem | M4: 259
C5: loonverhoging2 % | E5: alimentatie | F5: 420 | G5: kinder geb budget | H5: 0 | I5: bsgw | J5: 33.76 | L5: lucas | M5: 200
C6: afbetaling krien | D6: 0 | I6: ziggo | J6: 60 | L6: sophie | M6: 200
I7: NN pakketverzekering Confident limburg | J7: 72.66
I8: vodafoon | J8: 39.24 | M8: kinder gebonden budget
I9: NN | J9: 184.78 | M9: 2 kind op mijn naam met kinderbijslag
I10: auto verzek | J10: 40 | L10: sem | M10: 468
I11: wegenbelasting | J11: 70 | L11: lucas | M11: 468
I12: dela | J12: 10.93 | L12: sophie | M12: 200
I13: TAF | J13: 32
I14: tulip | J14: 20.95
A15: totalen | B15: =SUM(B2:B14) -> 0 | C15: totaal | D15: =SUM(D2:D14) -> 4290 | E15: totaal | F15: =SUM(F2:F14) -> 664.2 | G15: totaal toeslagen | H15: =H2+H3+H4+H5+H6+H7+H8 -> 0 | I15: tvabbo | J15: 22
I16: boete | J16: 25
A17: totalen netto inkomsten | C17: =D15 -> 4290 | D17: =(D15*1.02)+125 -> 4500.8 | E17: =(D17*1.02)+125 -> 4715.816
A19: totaal uitgaves | C19: =F15+J36+J22 -> 4320.61 | D19: =F15+J36+J22 -> 4320.61 | E19: =F15+J36+J22 -> 4320.61 | L19: 40
L20: 70
A21: totaal over te spenderen | C21: =C17-C19 -> -30.61 | D21: =D17-D19 -> 180.19 | E21: =E17-E19 -> 395.206 | G21: voorlopige aanslag 2025 | H21: 8774
I22: subtotaal | J22: =SUM(J2:J21) -> 2159.91
A24: bruto | C24: 6219 | D24: 6343.38 | E24: 6470.2 | I24: hond eten | J24: 80
A25: netto | C25: =3537.99 -> 3537.99 | D25: =D17 -> 4500.8 | E25: =E17 -> 4715.816 | I25: Benzine | J25: 0
A26: verschil bruto - netto | C26: =C24-C25 -> 2681.01 | D26: =D24-D25 -> 1842.58 | E26: =E24-E25 -> 1754.384 | I26: eten | J26: 600
A27: vakantiegeld netto | C27: 2539.41 | D27: 2700 | E27: 2900
A28: bruto verschil met huidige loon | D28: =D25-$C25 -> 962.81 | E28: =E25-$D25 -> 215.016
A29: hypo aftrek | C29: =D3 -> 550 | D29: =D3 -> 550 | E29: =D3 -> 550 | K29: 214 | L29: 3
A30: eenmalige ontvangsten | C30: 1000 | D30: 1000 | E30: 1000 | I30: sparen kids | J30: =6.5+5+5 -> 16.5
A31: Bijtelling leaseauto | C31: 605 | D31: 605 | E31: 605 | I31: sparen noodpotje | J31: 350 | K31: =J31+J32 -> 800 | L31: =J31*12 -> 4200
A32: jaarbasis | C32: 77550 | D32: 79101 | E32: 80683.02 | I32: DUO afbetaling | J32: 450 | K32: 500
A33: loonheffingsloon | C33: 25708 | D33: 26221 | E33: 26746 | L33: =J32*12 -> 5400 | M33: =50000/(L33+L31) -> 5.2083333
A34: toestingsinkomen | C34: =C32 -> 77550 | D34: =D32 -> 79101 | E34: =E32 -> 80683.02 | K34: ='[1]JB 2025 December'!$J$34 -> 384.31667
A35: hypotheek per maand | C35: =(J2*12)-(C29*12) -> 8473.08 | D35: =J2*12 -> 15073.08 | E35: =J2*12 -> 15073.08
A36: Netto per jaar | C36: =C32-C33 -> 51842 | D36: =D32-D33 -> 52880 | E36: =E32-E33 -> 53937.02 | I36: subtotaal | J36: =SUM(J24:J35) -> 1496.5
I37: Totaal | J37: =J22+J36 -> 3656.41
A40: bruto | B40: =C24 -> 6219
A41: netto | B41: =C24*0.5998 -> 3730.1562
A42: verschil bruto - netto | B42: =B40-B41 -> 2488.8438
A43: vakantiegeld | B43: =((B40-B47)*12)/100*8 -> 5389.44
A44: verschil met huidige loon | B44: =C25-B25 -> 3537.99
...
